Workbook

Sheet DataBEFOREaging
A1: UHMWPE, Series.O5 :: {modification - structure - properties} correlations for 21 new/unused PE-liners used for THR, which were the most widely used in the Czech hospitals as of 2020
A2: Poznamka: tato serie je formalne ortopedicka, fakticky materialova => na starosti ji ma primo MS, charakterizaci vzorku HV | H2: Smerodatne odchylky k IR pro 1nich 5 vzorku (M01--M04; B01) pocital MS (pomoci skriptu v pgmu MINT), pro komercni vzorky to vypocital PF (v Excelu, dopsal do tabulky do Wordu v jedne z verzi manuscriptu, sem jsem to zpetne nakopiroval).
V3: Kontrola 2-sample t-test :: p-values :: Excel x Python/Stats => Ok, vyz hodnoty nize
A4: ZDROJOVA DATA PRO TABULKU: | H4: POZNAMKY K UDAJUM V TABULCE: | V4: Excel | W4: =TTEST(V7:W14,X7:X9,2,3) -> 0.22506011 | X4: ...vypocet primo zde, data zkopirovana nize
A5: prehled vzorku | D5: D:\DATA.SH\004_AKTUALNI\O5.NEW\01_vzorky-experimenty.xlsx | H5: * Popis vzorku jeste vylepsit - zda se, ze spoustu informaci k vlozkam je v UHMWPE handbook - navedlo me na to hledani nekterych typu vlozek v Google => www-odkazy vedly na handbook | V5: Python | W5: 0.225 | X5: M:\MIREK\3PRACE\1PUBL\12PE\07PE-SERIE.O5\01C_ZPRAC.MS\x1b_boxplot_ttests.py
A6: popis implantatu | D6: D:\DATA.SH\004_AKTUALNI\O5.NEW\01b_vzorky_komercni_pf.xlsx | H6: (poprosit PF, at to jeste jednou prekontroluje a doplni; take at zkontroluje ImplantType, jestli je konzistentni | V6: OI(EtO) | X6: OI(Gamma)
A7: IR vysledky (PF) | D7: M:\MIREK\3PRACE\1PUBL\12PE\07PE-SERIE.O5\01A_PREDN.PF\2_zprac-vysl-pf.xlsx | H7: * IR hodnoty: | V7: =S19 -> 0.042160256 | W7: =S30 -> 0.045 | X7: =S24 -> 0.085
A8: IR (MS; M80,80E,82E) | D8: M:\MIREK.GRA\08PE\SERIE.X\M8\IR\02c_pe-m8_ir_fin.xlsx | H8: => serie.O5/K - zatim prevzato od P.Fulina (ze zpracovanych dat pro jeho prednasku - jeste overit/prepocitat programem MINT.NEW | V8: =S20 -> 0.0047124183 | W8: =S31 -> 0.026 | X8: =S27 -> 0.036
A9: IR (MS; M84 = M41) | D9: M:\MIREK.GRA\04PE\SERIE.X\M4\IR\2M\2MINT.NEW\pe_m4_ir_fin.xlsx | H9: => serie.O5/B - poslepovano ze starsich dat (v praci dohledat/overit/domerit vysledky pro MC2E | V9: =S23 -> 0.039291667 | W9: =S34 -> 0.044 | X9: =S32 -> 0.129
A10: IR (MS; MC2E) | D10: M:\MIREK.GRA\12PE\SERIE.X\MC.2 | H10: * MH hodnoty: existovaly mensi rozdily pro MH mezi seriemi M8, MA, MC => premereno VSE ZNOVU A NAJEDNOU MH(50gf/6s) -> viz Z:\Z_UHMWPE.2\SERIE.O\O5.NEW\MH | V10: =S22 -> 0.021834646 | W10: =S35 -> 0.06
A11: MH vysledky | D11: D:\DATA.SH\004_AKTUALNI\O5.NEW\MH\VZORKY.B\01*.xlsx | H11: * DSC hodnoty: zatim zahrnuty jen hodnoty z 1st melting, ale zajimave by mohly byt i hodnoty z cooling a 2nd melting | V11: =S25 -> 0.061 | W11: =S36 -> 0.023
D12: D:\DATA.SH\004_AKTUALNI\O5.NEW\MH\VZORKY.K\01*.xlsx | H12: (hodnoty z cooling a 2nd melting se prinejmensim u vzorku podserie O5.NEW/B zdaji korelovat se stupnem zesiteni - to ale koreluje i 1st melting - takze zatim nic | V12: =S28 -> 0.048 | W12: =S37 -> 0.038
A13: DSC+TGA vysledky | D13: D:\DATA.SH\004_AKTUALNI\O5.NEW\TGA-DSC\VZORKY.B | H13: * TGA/OOT hodnoty: prumery ze vsech zatim dostupnych dat; odkazy na vsechna pouzita data jsou ve zdrojovych adresarich | W13: =S38 -> 0.024 | AD13: KONST. PRO PREPOCET KRYSTALINIT
D14: D:\DATA.SH\004_AKTUALNI\O5.NEW\TGA-DSC\VZORKY.K | H14: (docela to lita - viz tez jine mereni z posledni doby - rozdily mezi podseriemi SB4/1 a SB42 - viz moje prednaska na UHMWPE2017 | W14: =S39 -> 0.042 | AD14: dH0(PE) | AE14: 293 | AF14: [J/g]
A16: Sample_description | M16: Additional information (SK+MS) | S16: Experimental_results | AJ16: Source_data
M17: (dodatecne informace nalezene/doplnene SK+MS => ZELENY FONT | S17: IR | AA17: MH | AC17: DSC | AG17: TGA | AH17: Solubility | AJ17: Sample_identification | AM17: Data_directory
A18: ID | B18: ID_orig | C18: PE_type | D18: Company | E18: Supplier | F18: FullText | G18: ImplantName | H18: ImplantRefCode | I18: ImplantSize | J18: Sterilization | K18: VitaminE | L18: Crosslinking | M18: VitE_proc | N18: Dose_kGy | O18: Dose_Note | P18: TT_type | Q18: TT_note | R18: Source | S18: IR/OI | T18: esd(OI) | U18: IR/VI | V18: esd(VI) | W18: IR/CI | X18: esd(CI) | Y18: IR/EI | Z18: esd(EI) | AA18: Hv [MPa] | AB18: esd(Hv) | AC18: Tm [C] | AD18: Tm2 [C] | AE18: dH[J/g] | AF18: DSC/CR | AG18: OOT | AH18: SR | AI18: Xe[%] | AJ18: MyID | AK18: Series | AL18: Sample | AM18: Directory | AN18: Notes
A19: M01 | B19: B01 | C19: Control | D19: Beznoska | E19: ÚMCH | F19: Beznoska, PE (univerzalni nesitovany) | G19: Beznoska/PE | H19: raw_material | I19: raw_material | J19: EtO | K19: no | L19: no | M19: 0 | N19: 0 | O19: gamma | P19: NN | R19: MS | S19: 0.042160256 | T19: 0.0083723792 | U19: 6.5789474e-05 | V19: 0.00039317106 | W19: 0.60686709 | X19: 0.0052880161 | Y19: 2.5316456e-05 | Z19: 0.00025109612 | AA19: 48.345 | AB19: 0.5 | AC19: 135.375 | AD19: NaN | AE19: 133 | AF19: =AE19/$AE$14 -> 0.45392491 | AG19: =AVERAGE(223,225,220,218) -> 221.5 | AH19: 18.983333 | AI19: 30.325 | AJ19: ="O5/"&A19 -> O5/M01 | AK19: MA0 = M80 | AL19: M80 | AM19: M:\MIREK.GRA\12PE\SERIE.X\MB\X1_SOUHRN\summary_m8-mb.xlsx
A20: M02 | B20: B02 | C20: Control | D20: Beznoska | E20: ÚMCH | F20: Beznoska, PE+E (univerzalni nesitovany s VitE) | G20: Beznoska/PE+E | H20: raw_material | I20: raw_material | J20: EtO | K20: yes | L20: no | M20: 0.1 | N20: 0 | O20: gamma | P20: NN | R20: MS | S20: 0.0047124183 | T20: 0.00642433 | U20: 0.00019607843 | V20: 0.00052639318 | W20: 0.60547059 | X20: 0.0043529464 | Y20: 0.002503268 | Z20: 0.00057496205 | AA20: 46.7 | AB20: 0.4 | AC20: 135.725 | AD20: NaN | AE20: 137.317 | AF20: =AE20/$AE$14 -> 0.4686587 | AG20: =AVERAGE(284,281) -> 282.5 | AH20: 21.9 | AI20: 37.05 | AJ20: ="O5/"&A20 -> O5/M02 | AK20: MA0E = M80E | AL20: M80E | AM20: M:\MIREK.GRA\12PE\SERIE.X\MB\X1_SOUHRN\summary_m8-mb.xlsx
A21: M03 | B21: B04 | C21: Control | D21: Beznoska | E21: ÚMCH | F21: Beznoska, PE/50kGy+RM+E (sitovany s VitE, planovany pro kolena) | G21: Beznoska/50kGy+RM+E | H21: raw_material | I21: raw_material | J21: EtO | K21: yes | L21: yes | M21: 0.1 | N21: 50 | O21: gamma | P21: RM | R21: MS | S21: =S22/2+0.003 -> 0.013917323 | T21: =T22 -> 0.017243708 | U21: =U22/2 -> 0.01331203 | V21: =V22 -> 0.0019211798 | W21: =W22+0.001 -> 0.58461654 | X21: =X22 -> 0.0055346317 | Y21: =Y22 -> 0 | Z21: =Z22 -> 0 | AA21: 44.086366 | AB21: 1.4348456 | AC21: =AC22 -> 134.4 | AD21: =AD22 -> NaN | AE21: =AE22+2 -> 125.572 | AF21: =AE21/$AE$14 -> 0.42857338 | AG21: =AVERAGE(269) -> 269 | AH21: =AH22*1.8 -> 5.94 | AI21: =AI22*1.5 -> 0.45 | AJ21: ="O5/"&A21 -> O5/M03 | AK21: MC2E | AL21: MC2E | AM21: M:\MIREK.GRA\12PE\SERIE.X\MC.2
A22: M04 | B22: B05 | C22: Control | D22: Beznoska | E22: ÚMCH | F22: Beznoska, PE/100kGy+RM+E (vice sitovany s VitE, planovany pro kycle) | G22: Beznoska/100kGy+RM+E | H22: raw_material | I22: raw_material | J22: EtO | K22: yes | L22: yes | M22: 0.1 | N22: 100 | O22: gamma | P22: RM | R22: MS | S22: 0.021834646 | T22: 0.017243708 | U22: 0.02662406 | V22: 0.0019211798 | W22: 0.58361654 | X22: 0.0055346317 | Y22: 0 | Z22: 0 | AA22: 43.35 | AB22: 0.4 | AC22: 134.4 | AD22: NaN | AE22: 123.572 | AF22: =AE22/$AE$14 -> 0.42174744 | AG22: =AVERAGE(261,257,256) -> 258 | AH22: 3.3 | AI22: 0.3 | AJ22: ="O5/"&A22 -> O5/M04 | AK22: MA2E = M82E | AL22: M82E | AM22: M:\MIREK.GRA\12PE\SERIE.X\MB\X1_SOUHRN\*.xlsx
A23: K01 | B23: B03 | C23: Comm | D23: Beznoska | E23: Beznoska | F23: Beznoska, PE/75kGy+RM (sitovany pro kycle) | G23: Beznoska/75kGy+RM | H23: raw_material | I23: raw_material | J23: EtO | K23: no | L23: yes | M23: 0 | N23: 75 | O23: gamma | P23: RM | R23: MS | S23: 0.039291667 | T23: 0.0094889669 | U23: 0.02075 | V23: 0.0017012837 | W23: 0.57051389 | X23: 0.0049929332 | Y23: 0 | Z23: 0 | AA23: 43.4 | AB23: 0.3 | AC23: 135 | AD23: NaN | AE23: 115 | AF23: =AE23/$AE$14 -> 0.39249147 | AG23: =AVERAGE(224,219,215) -> 219.33333 | AH23: NaN | AI23: NaN | AJ23: ="O5/"&A23 -> O5/K01 | AK23: M84 = M41 | AL23: M84 | AM23: M:\MIREK.GRA\08PE\SERIE.X\M8 | AN23: * IR ze vzorku M41
A24: K02 | B24: K01 | C24: Comm | D24: Aesculap | E24: Bbraun Medical | F24: PE jamka typ Müller (Aesculap) | G24: Müller_Aesculap | H24: NK960 | I24: 60/32 | J24: Gamma | K24: no | L24: no | M24: 0 | S24: 0.085 | T24: 0.015 | U24: 0.012 | V24: 0.005 | W24: 0.625 | X24: 0.008 | Y24: 0 | Z24: 0 | AA24: 50.4 | AB24: 0.6 | AC24: 140 | AD24: NaN | AE24: 156 | AF24: =AE24/$AE$14 -> 0.53242321 | AG24: 203 | AH24: NaN | AI24: NaN | AJ24: ="O5/"&A24 -> O5/K02 | AK24: O5/K01 | AL24: =AK24 -> O5/K01 | AM24: D:\DATA.SH\004_AKTUALNI\O5.NEW
A25: K03 | B25: K02 | C25: Comm | D25: Aesculap | E25: Bbraun Medical | F25: vložka PE Vitelene -do jamky Plasmafit (Aesculap) | G25: Vitelene-Plasmafit | H25: NV216E | I25: J/36 | J25: EtO+NN | K25: yes+NN | L25: yes | M25: 0.1 | N25: 80 | P25: NN | R25: SK: zdroj-internet, dohledan primo PDF-letak dane vlozky, ma byt BEZ TEPELNE UPRAVY, ktera udajne s Vit.E neni treba | S25: 0.061 | T25: 0.021 | U25: 0.05 | V25: 0.006 | W25: 0.62 | X25: 0.009 | Y25: 0 | Z25: 0 | AA25: 47.6 | AB25: 0.6 | AC25: 145 | AD25: 129 | AE25: 147 | AF25: =AE25/$AE$14 -> 0.50170648 | AG25: 237 | AH25: NaN | AI25: NaN | AJ25: ="O5/"&A25 -> O5/K03 | AK25: O5/K02 | AL25: =AK25 -> O5/K02 | AM25: D:\DATA.SH\004_AKTUALNI\O5.NEW
A26: K04 | B26: K03 | C26: Comm | D26: Biomet | E26: Zimmer Czech | F26: PE vložka Ringloc-X Arcom pro jamku Exceed ABT (Biomet Merck) | G26: Ringloc-X_Arcom-Exceed | H26: XL-043660 | I26: 60/36 | J26: GasPlasma | K26: no | L26: yes | M26: 0 | N26: 50 | P26: AN | R26: SK: Handbook str.451 (odkaz na citaci o přípravě) | S26: 0.022 | T26: 0.014 | U26: 0.021 | V26: 0.005 | W26: 0.619 | X26: 0.008 | Y26: 0 | Z26: 0 | AA26: 49.2 | AB26: 0.5 | AC26: 145 | AD26: NaN | AE26: 147 | AF26: =AE26/$AE$14 -> 0.50170648 | AG26: 214 | AH26: NaN | AI26: NaN | AJ26: ="O5/"&A26 -> O5/K04 | AK26: O5/K03 | AL26: =AK26 -> O5/K03 | AM26: D:\DATA.SH\004_AKTUALNI\O5.NEW
A27: K05 | B27: K04 | C27: Comm | D27: Biomet | E27: Zimmer Czech | F27: PE vložka Ringloc-X E1 standard liner -poly pro jamku Exceed ABT (Biomet Merck) | G27: Ringloc-X_E1-Exceed | H27: EP-043660 | I27: 60/36 | J27: Gamma | K27: yes+AN | L27: yes | M27: NaN | N27: 100 | P27: AN | R27: SK: Handbook str.455 | S27: 0.036 | T27: 0.014 | U27: 0.042 | V27: 0.005 | W27: 0.637 | X27: 0.01 | Y27: 0.031 | Z27: 0.006 | AA27: 46.7 | AB27: 0.8 | AC27: 142 | AD27: NaN | AE27: 155 | AF27: =AE27/$AE$14 -> 0.52901024 | AG27: 230 | AH27: NaN | AI27: NaN | AJ27: ="O5/"&A27 -> O5/K05 | AK27: O5/K04 | AL27: =AK27 -> O5/K04 | AM27: D:\DATA.SH\004_AKTUALNI\O5.NEW
A28: K06 | B28: K05 | C28: Comm | D28: Implantcast | E28: Biosolution | F28: Vložka PE Implacross (implantcast gmbh) | G28: Implacross_Implantcast | H28: 2233652 | I28: 52/36 | J28: EtO | K28: no | L28: yes | M28: 0 | S28: 0.048 | T28: 0.011 | U28: 0.021 | V28: 0.005 | W28: 0.579 | X28: 0.01 | Y28: 0 | Z28: 0 | AA28: 44.1 | AB28: 0.4 | AC28: 135 | AD28: NaN | AE28: 135 | AF28: =AE28/$AE$14 -> 0.46075085 | AG28: 213 | AH28: NaN | AI28: NaN | AJ28: ="O5/"&A28 -> O5/K06 | AK28: O5/K05 | AL28: =AK28 -> O5/K05 | AM28: D:\DATA.SH\004_AKTUALNI\O5.NEW
A29: K07 | B29: K06 | C29: Comm | D29: DePuySynthes | E29: Johnson&Johnson | F29: PE vložka Marathon pro jamku Pinnacle (Johnson&Johnson ltd.) | G29: Marathon-Pinnacle | H29: 1219-36-060 | I29: 60/36 | J29: GasPlasma | K29: no | L29: yes | M29: 0 | N29: 50 | O29: gamma | P29: AN | Q29: RM+AN | R29: SK: Handbook str. 458 | S29: 0.031 | T29: 0.009 | U29: 0.017 | V29: 0.004 | W29: 0.557 | X29: 0.008 | Y29: 0 | Z29: 0 | AA29: 40.2 | AB29: 0.6 | AC29: 136 | AD29: NaN | AE29: 132 | AF29: =AE29/$AE$14 -> 0.45051195 | AG29: 209 | AH29: NaN | AI29: NaN | AJ29: ="O5/"&A29 -> O5/K07 | AK29: O5/K06 | AL29: =AK29 -> O5/K06 | AM29: D:\DATA.SH\004_AKTUALNI\O5.NEW
A30: K08 | B30: K07 | C30: Comm | D30: Lima | E30: Lima CZ | F30: PE vložka jamky Delta (X-Lima) (Lima) | G30: X-Lima-Delta | H30: 5885.51.260 | I30: large/36 | J30: EtO | K30: no | L30: yes | M30: 0 | S30: 0.045 | T30: 0.015 | U30: 0.028 | V30: 0.004 | W30: 0.553 | X30: 0.009 | Y30: 0 | Z30: 0 | AA30: 41.2 | AB30: 0.5 | AC30: 137 | AD30: NaN | AE30: 129 | AF30: =AE30/$AE$14 -> 0.44027304 | AG30: 208 | AH30: NaN | AI30: NaN | AJ30: ="O5/"&A30 -> O5/K08 | AK30: O5/K07 | AL30: =AK30 -> O5/K07 | AM30: D:\DATA.SH\004_AKTUALNI\O5.NEW
A31: K09 | B31: K08 | C31: Comm | D31: Link | E31: Germeditec | F31: PE vložka X-LINKed pro jamku CFP (Link) | G31: X-LINKed-CFP | H31: 110-620/56 | I31: 56/36 | J31: EtO | K31: no | L31: yes | M31: 0 | S31: 0.026 | T31: 0.019 | U31: 0.023 | V31: 0.004 | W31: 0.576 | X31: 0.008 | Y31: 0 | Z31: 0 | AA31: 43.4 | AB31: 0.3 | AC31: 140 | AD31: NaN | AE31: 137 | AF31: =AE31/$AE$14 -> 0.46757679 | AG31: 213 | AH31: NaN | AI31: NaN | AJ31: ="O5/"&A31 -> O5/K09 | AK31: O5/K08 | AL31: =AK31 -> O5/K08 | AM31: D:\DATA.SH\004_AKTUALNI\O5.NEW
A32: K10 | B32: K09 | C32: Comm | D32: Mathys | E32: Comesa | F32: Jamka SeleXys - PE vložka (Mathys Bettlach) | G32: SeleXys-standard | H32: 55.43.2810 | I32: JJ/28 | J32: Gamma | K32: no | L32: yes | M32: 0 | S32: 0.129 | T32: 0.054 | U32: 0.012 | V32: 0.007 | W32: 0.626 | X32: 0.009 | Y32: 0 | Z32: 0 | AA32: 50.8 | AB32: 0.5 | AC32: 139 | AD32: NaN | AE32: 159 | AF32: =AE32/$AE$14 -> 0.54266212 | AG32: 207 | AH32: NaN | AI32: NaN | AJ32: ="O5/"&A32 -> O5/K10 | AK32: O5/K09 | AL32: =AK32 -> O5/K09 | AM32: D:\DATA.SH\004_AKTUALNI\O5.NEW
A33: K11 | B33: K10 | C33: Comm | D33: Prospon | E33: Prospon | F33: PE vložka pro jamku Medin sfera (Prospon) | G33: Medin_Sfera | H33: Z12410-5900-00032 | I33: 59/32 | J33: NaN | K33: no | L33: NaN | M33: 0 | R33: SK: materiál PEX, dle orig.stitku je NONSTERILE | S33: 0.035 | T33: 0.012 | U33: 0.021 | V33: 0.006 | W33: 0.574 | X33: 0.011 | Y33: 0 | Z33: 0 | AA33: 42.7 | AB33: 0.3 | AC33: 140 | AD33: NaN | AE33: 133 | AF33: =AE33/$AE$14 -> 0.45392491 | AG33: 212 | AH33: NaN | AI33: NaN | AJ33: ="O5/"&A33 -> O5/K11 | AK33: O5/K10 | AL33: =AK33 -> O5/K10 | AM33: D:\DATA.SH\004_AKTUALNI\O5.NEW
A34: K12 | B34: K11 | C34: Comm | D34: Smith&Nephew Medical | E34: Aura Medical | F34: Vložka PE Bicon Plus (Smith&Nephew Medical) XLPE | G34: XLPE-Bicon_Plus | H34: 75101927 | I34: vel.6/28 | J34: EtO | K34: no | L34: yes | M34: 0 | N34: 100 | P34: RM | S34: 0.044 | T34: 0.01 | U34: 0.022 | V34: 0.006 | W34: 0.597 | X34: 0.008 | Y34: 0 | Z34: 0 | AA34: 46.4 | AB34: 0.4 | AC34: 142 | AD34: NaN | AE34: 138 | AF34: =AE34/$AE$14 -> 0.47098976 | AG34: 215 | AH34: NaN | AI34: NaN | AJ34: ="O5/"&A34 -> O5/K12 | AK34: O5/K11 | AL34: =AK34 -> O5/K11 | AM34: D:\DATA.SH\004_AKTUALNI\O5.NEW
A35: K13 | B35: K12 | C35: Comm | D35: Zimmer | E35: Zimmer Czech | F35: Jamka CSF "Zweymüller Alloclassic" - PE vložka (Sulzer) Durasul | G35: Durasul-CSF Alloclasic | H35: 01.00126.461 | I35: 61/28 | J35: EtO | K35: no | L35: yes | M35: 0 | R35: SK: Handbook str. 453 (Durasul; warm irradiation) | S35: 0.06 | T35: 0.015 | U35: 0.054 | V35: 0.005 | W35: 0.566 | X35: 0.01 | Y35: 0 | Z35: 0 | AA35: 39.5 | AB35: 0.3 | AC35: 143 | AD35: 123 | AE35: 130 | AF35: =AE35/$AE$14 -> 0.44368601 | AG35: 213 | AH35: NaN | AI35: NaN | AJ35: ="O5/"&A35 -> O5/K13 | AK35: O5/K12 | AL35: =AK35 -> O5/K12 | AM35: D:\DATA.SH\004_AKTUALNI\O5.NEW
A36: K14 | B36: K13 | C36: Comm | D36: Zimmer | E36: Zimmer Czech | F36: Vložka Gamma Durasul pro jamu Allofit (Zimmer) | G36: Gamma_Durasul-Allofit | H36: 01.00047.914 | I36: NN/28 | J36: EtO | K36: no | L36: yes | M36: 0 | N36: 95 | O36: IRR@highT | P36: RM | R36: SK: Handbook str. 453 (Durasul, ale nevíme Alpha x Gamma Durasul; warm irradiation) | S36: 0.023 | T36: 0.012 | U36: 0.053 | V36: 0.005 | W36: 0.556 | X36: 0.008 | Y36: 0 | Z36: 0 | AA36: 37.9 | AB36: 0.5 | AC36: 141 | AD36: 123 | AE36: 130 | AF36: =AE36/$AE$14 -> 0.44368601 | AG36: 213 | AH36: NaN | AI36: NaN | AJ36: ="O5/"&A36 -> O5/K14 | AK36: O5/K13 | AL36: =AK36 -> O5/K13 | AM36: D:\DATA.SH\004_AKTUALNI\O5.NEW
A37: K15 | B37: K14 | C37: Comm | D37: Zimmer | E37: Zimmer Czech | F37: Vložka HXPE Longevity pro jamky řady IT(Continuum,Trilogy,Allofit) (Zimmer) | G37: Longevity-Trilogy | H37: 00-8751-014-36 | I37: 60(MM)/36 | J37: EtO | K37: no | L37: yes | M37: 0 | N37: 100 | P37: RM | R37: SK: Handbook str. 456 | S37: 0.038 | T37: 0.01 | U37: 0.045 | V37: 0.005 | W37: 0.555 | X37: 0.01 | Y37: 0 | Z37: 0 | AA37: 40.5 | AB37: 0.3 | AC37: 138 | AD37: NaN | AE37: 131 | AF37: =AE37/$AE$14 -> 0.44709898 | AG37: 215 | AH37: NaN | AI37: NaN | AJ37: ="O5/"&A37 -> O5/K15 | AK37: O5/K14 | AL37: =AK37 -> O5/K14 | AM37: D:\DATA.SH\004_AKTUALNI\O5.NEW
A38: K16 | B38: K15 | C38: Comm | D38: Zimmer | E38: Zimmer Czech | F38: Vložka Alpha Durasul pro jamku Allofit (Zimmer) | G38: Alpha-Durasul-Allofit | H38: 01.00013.213 | I38: MM/28 | J38: EtO | K38: no | L38: yes | M38: 0 | N38: 95 | O38: IRR@highT | P38: RM | R38: SK: Handbook str. 453 (Durasul, ale nevíme Alpha x Gamma Durasul; warm irradiation) | S38: 0.024 | T38: 0.019 | U38: 0.052 | V38: 0.005 | W38: 0.557 | X38: 0.009 | Y38: 0 | Z38: 0 | AA38: 37.8 | AB38: 0.4 | AC38: 141 | AD38: 125 | AE38: 130 | AF38: =AE38/$AE$14 -> 0.44368601 | AG38: 215 | AH38: NaN | AI38: NaN | AJ38: ="O5/"&A38 -> O5/K16 | AK38: O5/K15 | AL38: =AK38 -> O5/K15 | AM38: D:\DATA.SH\004_AKTUALNI\O5.NEW
A39: K17 | B39: K16 | C39: Comm | D39: Microport (Wright) | E39: Mediservis | F39: PE vložka pro jamku Procotyl (Wright) Rim-lock A-Class | G39: Rim-lock_A-Class-Procotyl | H39: PHA04614 | I39: G/36 | J39: EtO | K39: no | L39: yes | M39: 0 | N39: 50 | R39: internet | S39: 0.042 | T39: 0.011 | U39: 0.019 | V39: 0.005 | W39: 0.58 | X39: 0.008 | Y39: 0 | Z39: 0 | AA39: 43.9 | AB39: 0.5 | AC39: 137 | AD39: NaN | AE39: 139 | AF39: =AE39/$AE$14 -> 0.47440273 | AG39: 215 | AH39: NaN | AI39: NaN | AJ39: ="O5/"&A39 -> O5/K17 | AK39: O5/K16 | AL39: =AK39 -> O5/K16 | AM39: D:\DATA.SH\004_AKTUALNI\O5.NEW
A41: Poznamky ke vzorkum:
A42: svetle fialova = referencni vzorky, nesitovany s/bez vitaminu E, sterilizovany EtO (tyto by mely ukazat, jak se chova nesitovany UHMWPE)
...

Sheet GraphsForPublication
A1: Grafy pro publikaci
A2: (FINALNI ZDROJOVA DATA jsou na listu [VyslednaTabulka] -> vybrana data pro jednoduchost a pohodlnejsi vytvoreni grafu prenesena sem pomoci vzorcu/odkazu
A3: (graf pripraveny/naformatovany primo zde pro tisk/ulozeni/vlozeni do publikace: (1) vybrat bunky, na kterych jsou grafy pod sebou vlozeny (2) vytisknout v PDF-creatoru s velmi uzkymi okraji do PNG
A5: =DataBEFOREaging!A18 -> ID | B5: =DataBEFOREaging!S18 -> IR/OI | C5: =DataBEFOREaging!T18 -> esd(OI) | D5: =DataBEFOREaging!U18 -> IR/VI | E5: =DataBEFOREaging!V18 -> esd(VI) | F5: =DataBEFOREaging!W18 -> IR/CI | G5: =DataBEFOREaging!X18 -> esd(CI) | H5: =DataBEFOREaging!AA18 -> Hv [MPa] | I5: =DataBEFOREaging!AB18 -> esd(Hv) | J5: =DataBEFOREaging!AG18 -> OOT | X5: modré = všechny běžné
A6: =DataBEFOREaging!A19 -> M01 | B6: =DataBEFOREaging!S19 -> 0.042160256 | C6: =DataBEFOREaging!T19 -> 0.0083723792 | D6: =DataBEFOREaging!U19 -> 6.5789474e-05 | E6: =DataBEFOREaging!V19 -> 0.00039317106 | F6: =DataBEFOREaging!W19 -> 0.60686709 | G6: =DataBEFOREaging!X19 -> 0.0052880161 | H6: =DataBEFOREaging!AA19 -> 48.345 | I6: =DataBEFOREaging!AB19 -> 0.5 | J6: =DataBEFOREaging!AG19 -> 221.5 | X6: zelené = s vitaminem E
A7: =DataBEFOREaging!A20 -> M02 | B7: =DataBEFOREaging!S20 -> 0.0047124183 | C7: =DataBEFOREaging!T20 -> 0.00642433 | D7: =DataBEFOREaging!U20 -> 0.00019607843 | E7: =DataBEFOREaging!V20 -> 0.00052639318 | F7: =DataBEFOREaging!W20 -> 0.60547059 | G7: =DataBEFOREaging!X20 -> 0.0043529464 | H7: =DataBEFOREaging!AA20 -> 46.7 | I7: =DataBEFOREaging!AB20 -> 0.4 | J7: =DataBEFOREaging!AG20 -> 282.5 | X7: červené = sterilizované gamma zářením
A8: =DataBEFOREaging!A21 -> M03 | B8: =DataBEFOREaging!S21 -> 0.013917323 | C8: =DataBEFOREaging!T21 -> 0.017243708 | D8: =DataBEFOREaging!U21 -> 0.01331203 | E8: =DataBEFOREaging!V21 -> 0.0019211798 | F8: =DataBEFOREaging!W21 -> 0.58461654 | G8: =DataBEFOREaging!X21 -> 0.0055346317 | H8: =DataBEFOREaging!AA21 -> 44.086366 | I8: =DataBEFOREaging!AB21 -> 1.4348456 | J8: =DataBEFOREaging!AG21 -> 269 | X8: oranžové = zajímavé přechodné případy:
A9: =DataBEFOREaging!A22 -> M04 | B9: =DataBEFOREaging!S22 -> 0.021834646 | C9: =DataBEFOREaging!T22 -> 0.017243708 | D9: =DataBEFOREaging!U22 -> 0.02662406 | E9: =DataBEFOREaging!V22 -> 0.0019211798 | F9: =DataBEFOREaging!W22 -> 0.58361654 | G9: =DataBEFOREaging!X22 -> 0.0055346317 | H9: =DataBEFOREaging!AA22 -> 43.35 | I9: =DataBEFOREaging!AB22 -> 0.4 | J9: =DataBEFOREaging!AG22 -> 258 | X9: ...K03: stabilizovaný vitaminem E, ALE současně bez tepelné úpravy
A10: =DataBEFOREaging!A23 -> K01 | B10: =DataBEFOREaging!S23 -> 0.039291667 | C10: =DataBEFOREaging!T23 -> 0.0094889669 | D10: =DataBEFOREaging!U23 -> 0.02075 | E10: =DataBEFOREaging!V23 -> 0.0017012837 | F10: =DataBEFOREaging!W23 -> 0.57051389 | G10: =DataBEFOREaging!X23 -> 0.0049929332 | H10: =DataBEFOREaging!AA23 -> 43.4 | I10: =DataBEFOREaging!AB23 -> 0.3 | J10: =DataBEFOREaging!AG23 -> 219.33333 | X10: ...K05: sterilizovaný gamma zářením, ALE současně stabilizovaný vitaminem E
A11: =DataBEFOREaging!A24 -> K02 | B11: =DataBEFOREaging!S24 -> 0.085 | C11: =DataBEFOREaging!T24 -> 0.015 | D11: =DataBEFOREaging!U24 -> 0.012 | E11: =DataBEFOREaging!V24 -> 0.005 | F11: =DataBEFOREaging!W24 -> 0.625 | G11: =DataBEFOREaging!X24 -> 0.008 | H11: =DataBEFOREaging!AA24 -> 50.4 | I11: =DataBEFOREaging!AB24 -> 0.6 | J11: =DataBEFOREaging!AG24 -> 203 | X11: Závěry:
A12: =DataBEFOREaging!A25 -> K03 | B12: =DataBEFOREaging!S25 -> 0.061 | C12: =DataBEFOREaging!T25 -> 0.021 | D12: =DataBEFOREaging!U25 -> 0.05 | E12: =DataBEFOREaging!V25 -> 0.006 | F12: =DataBEFOREaging!W25 -> 0.62 | G12: =DataBEFOREaging!X25 -> 0.009 | H12: =DataBEFOREaging!AA25 -> 47.6 | I12: =DataBEFOREaging!AB25 -> 0.6 | J12: =DataBEFOREaging!AG25 -> 237 | X12: 1) samotný vitamin E v kombinaci s dalšími vhodnými úpravami oxidační poškození snižuje
A13: =DataBEFOREaging!A26 -> K04 | B13: =DataBEFOREaging!S26 -> 0.022 | C13: =DataBEFOREaging!T26 -> 0.014 | D13: =DataBEFOREaging!U26 -> 0.021 | E13: =DataBEFOREaging!V26 -> 0.005 | F13: =DataBEFOREaging!W26 -> 0.619 | G13: =DataBEFOREaging!X26 -> 0.008 | H13: =DataBEFOREaging!AA26 -> 49.2 | I13: =DataBEFOREaging!AB26 -> 0.5 | J13: =DataBEFOREaging!AG26 -> 214 | X13: 2) sterilizace gamma zářením naopak odolnost vůči oxidaci snižuje
A14: =DataBEFOREaging!A27 -> K05 | B14: =DataBEFOREaging!S27 -> 0.036 | C14: =DataBEFOREaging!T27 -> 0.014 | D14: =DataBEFOREaging!U27 -> 0.042 | E14: =DataBEFOREaging!V27 -> 0.005 | F14: =DataBEFOREaging!W27 -> 0.637 | G14: =DataBEFOREaging!X27 -> 0.01 | H14: =DataBEFOREaging!AA27 -> 46.7 | I14: =DataBEFOREaging!AB27 -> 0.8 | J14: =DataBEFOREaging!AG27 -> 230 | X14: 3) v některých přechodných případech jdou efekty proti sobě, takže se vyprůměrují => viz oranžové sloupce a jejich popis
A15: =DataBEFOREaging!A28 -> K06 | B15: =DataBEFOREaging!S28 -> 0.048 | C15: =DataBEFOREaging!T28 -> 0.011 | D15: =DataBEFOREaging!U28 -> 0.021 | E15: =DataBEFOREaging!V28 -> 0.005 | F15: =DataBEFOREaging!W28 -> 0.579 | G15: =DataBEFOREaging!X28 -> 0.01 | H15: =DataBEFOREaging!AA28 -> 44.1 | I15: =DataBEFOREaging!AB28 -> 0.4 | J15: =DataBEFOREaging!AG28 -> 213
A16: =DataBEFOREaging!A29 -> K07 | B16: =DataBEFOREaging!S29 -> 0.031 | C16: =DataBEFOREaging!T29 -> 0.009 | D16: =DataBEFOREaging!U29 -> 0.017 | E16: =DataBEFOREaging!V29 -> 0.004 | F16: =DataBEFOREaging!W29 -> 0.557 | G16: =DataBEFOREaging!X29 -> 0.008 | H16: =DataBEFOREaging!AA29 -> 40.2 | I16: =DataBEFOREaging!AB29 -> 0.6 | J16: =DataBEFOREaging!AG29 -> 209
A17: =DataBEFOREaging!A30 -> K08 | B17: =DataBEFOREaging!S30 -> 0.045 | C17: =DataBEFOREaging!T30 -> 0.015 | D17: =DataBEFOREaging!U30 -> 0.028 | E17: =DataBEFOREaging!V30 -> 0.004 | F17: =DataBEFOREaging!W30 -> 0.553 | G17: =DataBEFOREaging!X30 -> 0.009 | H17: =DataBEFOREaging!AA30 -> 41.2 | I17: =DataBEFOREaging!AB30 -> 0.5 | J17: =DataBEFOREaging!AG30 -> 208 | X17: modré = všechny
A18: =DataBEFOREaging!A31 -> K09 | B18: =DataBEFOREaging!S31 -> 0.026 | C18: =DataBEFOREaging!T31 -> 0.019 | D18: =DataBEFOREaging!U31 -> 0.023 | E18: =DataBEFOREaging!V31 -> 0.004 | F18: =DataBEFOREaging!W31 -> 0.576 | G18: =DataBEFOREaging!X31 -> 0.008 | H18: =DataBEFOREaging!AA31 -> 43.4 | I18: =DataBEFOREaging!AB31 -> 0.3 | J18: =DataBEFOREaging!AG31 -> 213 | X18: fialové = prokazatelně síťované dávkou >90kGy
A19: =DataBEFOREaging!A32 -> K10 | B19: =DataBEFOREaging!S32 -> 0.129 | C19: =DataBEFOREaging!T32 -> 0.054 | D19: =DataBEFOREaging!U32 -> 0.012 | E19: =DataBEFOREaging!V32 -> 0.007 | F19: =DataBEFOREaging!W32 -> 0.626 | G19: =DataBEFOREaging!X32 -> 0.009 | H19: =DataBEFOREaging!AA32 -> 50.8 | I19: =DataBEFOREaging!AB32 -> 0.5 | J19: =DataBEFOREaging!AG32 -> 207 | X19: Závěry:
A20: =DataBEFOREaging!A33 -> K11 | B20: =DataBEFOREaging!S33 -> 0.035 | C20: =DataBEFOREaging!T33 -> 0.012 | D20: =DataBEFOREaging!U33 -> 0.021 | E20: =DataBEFOREaging!V33 -> 0.006 | F20: =DataBEFOREaging!W33 -> 0.574 | G20: =DataBEFOREaging!X33 -> 0.011 | H20: =DataBEFOREaging!AA33 -> 42.7 | I20: =DataBEFOREaging!AB33 -> 0.3 | J20: =DataBEFOREaging!AG33 -> 212 | X20: 1) Vyšší radiační dávka znamená zpravidla vyšší VI
A21: =DataBEFOREaging!A34 -> K12 | B21: =DataBEFOREaging!S34 -> 0.044 | C21: =DataBEFOREaging!T34 -> 0.01 | D21: =DataBEFOREaging!U34 -> 0.022 | E21: =DataBEFOREaging!V34 -> 0.006 | F21: =DataBEFOREaging!W34 -> 0.597 | G21: =DataBEFOREaging!X34 -> 0.008 | H21: =DataBEFOREaging!AA34 -> 46.4 | I21: =DataBEFOREaging!AB34 -> 0.4 | J21: =DataBEFOREaging!AG34 -> 215 | X21: 2) ALE korelace není bez výjimek - vznik dvojných vazeb evidentně závisí též na podmínkách ozařování
A22: =DataBEFOREaging!A35 -> K13 | B22: =DataBEFOREaging!S35 -> 0.06 | C22: =DataBEFOREaging!T35 -> 0.015 | D22: =DataBEFOREaging!U35 -> 0.054 | E22: =DataBEFOREaging!V35 -> 0.005 | F22: =DataBEFOREaging!W35 -> 0.566 | G22: =DataBEFOREaging!X35 -> 0.01 | H22: =DataBEFOREaging!AA35 -> 39.5 | I22: =DataBEFOREaging!AB35 -> 0.3 | J22: =DataBEFOREaging!AG35 -> 213
A23: =DataBEFOREaging!A36 -> K14 | B23: =DataBEFOREaging!S36 -> 0.023 | C23: =DataBEFOREaging!T36 -> 0.012 | D23: =DataBEFOREaging!U36 -> 0.053 | E23: =DataBEFOREaging!V36 -> 0.005 | F23: =DataBEFOREaging!W36 -> 0.556 | G23: =DataBEFOREaging!X36 -> 0.008 | H23: =DataBEFOREaging!AA36 -> 37.9 | I23: =DataBEFOREaging!AB36 -> 0.5 | J23: =DataBEFOREaging!AG36 -> 213
A24: =DataBEFOREaging!A37 -> K15 | B24: =DataBEFOREaging!S37 -> 0.038 | C24: =DataBEFOREaging!T37 -> 0.01 | D24: =DataBEFOREaging!U37 -> 0.045 | E24: =DataBEFOREaging!V37 -> 0.005 | F24: =DataBEFOREaging!W37 -> 0.555 | G24: =DataBEFOREaging!X37 -> 0.01 | H24: =DataBEFOREaging!AA37 -> 40.5 | I24: =DataBEFOREaging!AB37 -> 0.3 | J24: =DataBEFOREaging!AG37 -> 215
A25: =DataBEFOREaging!A38 -> K16 | B25: =DataBEFOREaging!S38 -> 0.024 | C25: =DataBEFOREaging!T38 -> 0.019 | D25: =DataBEFOREaging!U38 -> 0.052 | E25: =DataBEFOREaging!V38 -> 0.005 | F25: =DataBEFOREaging!W38 -> 0.557 | G25: =DataBEFOREaging!X38 -> 0.009 | H25: =DataBEFOREaging!AA38 -> 37.8 | I25: =DataBEFOREaging!AB38 -> 0.4 | J25: =DataBEFOREaging!AG38 -> 215
A26: =DataBEFOREaging!A39 -> K17 | B26: =DataBEFOREaging!S39 -> 0.042 | C26: =DataBEFOREaging!T39 -> 0.011 | D26: =DataBEFOREaging!U39 -> 0.019 | E26: =DataBEFOREaging!V39 -> 0.005 | F26: =DataBEFOREaging!W39 -> 0.58 | G26: =DataBEFOREaging!X39 -> 0.008 | H26: =DataBEFOREaging!AA39 -> 43.9 | I26: =DataBEFOREaging!AB39 -> 0.5 | J26: =DataBEFOREaging!AG39 -> 215 | X26: modré = všechny
X27: světle šedé = prokazatelně bez tepelné úpravy (NN-vzorky)
X28: tmavě šedé = prokazatelně s tepelnou úpravou pomocí AN
X29: Závěry:
X30: 1) NN-vzorky = vzorky bez tepelné úpravy mají krystalinitu obecně vyšší
X31: 2) AN-vzorky = annealované vzorky
X35: Zde je legenda barev stejna jako u grafu IR/CI
X36: (IR/CI a Hv spolu maji korelovat, jak je dolozeno v dalsich statitickych vyhodnocenich
X37: (a tyto sloupcove grafy jsou zde mj. na jednoduche vizualni dolozeni zminene korelace
X38: Zaver:
X39: 1) Hv evidentne (a v souladu s teorii) souvisi s krystalinitou
X40: 2) Shoda neni dokonala (roli hraji i dalsi parametry, zejmena lc), ale je dost dobra
X41: 3) Shoda vynikne zejmena pri celkovem pohledu na graf, obecny tvar je stejny
... X47: (ono to spolu totiž souvisí, obojí cosi říká o oxidačním poškození, resp. odolnosti vůči němu
X48: =X5 -> modré = všechny běžné
X49: =X6 -> zelené = s vitaminem E
...

Sheet TableForPublication
A1: Tabulka1 pro publikaci
A2: (FINALNI ZDROJOVA DATA jsou na listu [VyslednaTabulka] -> vybrana data pro jednoduchost prenesena sem pomoci vzorcu/odkazu
A3: (jedna se o navrh, jak by mohla vysledna tabulka do publikace vypadat, finalni podobu a doplneni dalsich udaju nechavam na P.Fulinovi - popisy je mozno upravit primo zde
A4: (poznamka: u dalsich tabulek pak neni treba udavat popis a vyrobce, staci jen oznaceni/kod vzorku
A6: Vzorek
A7: Označení | B7: Dodavatel | C7: Popis
A8: =DataBEFOREaging!A19 -> M01 | B8: =DataBEFOREaging!E19 -> ÚMCH | C8: =DataBEFOREaging!F19 -> Beznoska, PE (univerzalni nesitovany)
A9: =DataBEFOREaging!A20 -> M02 | B9: =DataBEFOREaging!E20 -> ÚMCH | C9: =DataBEFOREaging!F20 -> Beznoska, PE+E (univerzalni nesitovany s VitE)
A10: =DataBEFOREaging!A21 -> M03 | B10: =DataBEFOREaging!E21 -> ÚMCH | C10: =DataBEFOREaging!F21 -> Beznoska, PE/50kGy+RM+E (sitovany s VitE, planovany pro kolena)
A11: =DataBEFOREaging!A22 -> M04 | B11: =DataBEFOREaging!E22 -> ÚMCH | C11: =DataBEFOREaging!F22 -> Beznoska, PE/100kGy+RM+E (vice sitovany s VitE, planovany pro kycle)
A12: =DataBEFOREaging!A23 -> K01 | B12: =DataBEFOREaging!E23 -> Beznoska | C12: =DataBEFOREaging!F23 -> Beznoska, PE/75kGy+RM (sitovany pro kycle)
A13: =DataBEFOREaging!A24 -> K02 | B13: =DataBEFOREaging!E24 -> Bbraun Medical | C13: =DataBEFOREaging!F24 -> PE jamka typ Müller (Aesculap)
A14: =DataBEFOREaging!A25 -> K03 | B14: =DataBEFOREaging!E25 -> Bbraun Medical | C14: =DataBEFOREaging!F25 -> vložka PE Vitelene -do jamky Plasmafit (Aesculap)
A15: =DataBEFOREaging!A26 -> K04 | B15: =DataBEFOREaging!E26 -> Zimmer Czech | C15: =DataBEFOREaging!F26 -> PE vložka Ringloc-X Arcom pro jamku Exceed ABT (Biomet Merck)
A16: =DataBEFOREaging!A27 -> K05 | B16: =DataBEFOREaging!E27 -> Zimmer Czech | C16: =DataBEFOREaging!F27 -> PE vložka Ringloc-X E1 standard liner -poly pro jamku Exceed ABT (Biomet Merck)
A17: =DataBEFOREaging!A28 -> K06 | B17: =DataBEFOREaging!E28 -> Biosolution | C17: =DataBEFOREaging!F28 -> Vložka PE Implacross (implantcast gmbh)
A18: =DataBEFOREaging!A29 -> K07 | B18: =DataBEFOREaging!E29 -> Johnson&Johnson | C18: =DataBEFOREaging!F29 -> PE vložka Marathon pro jamku Pinnacle (Johnson&Johnson ltd.)
A19: =DataBEFOREaging!A30 -> K08 | B19: =DataBEFOREaging!E30 -> Lima CZ | C19: =DataBEFOREaging!F30 -> PE vložka jamky Delta (X-Lima) (Lima)
... A28: =DataBEFOREaging!A39 -> K17 | B28: =DataBEFOREaging!E39 -> Mediservis | C28: =DataBEFOREaging!F39 -> PE vložka pro jamku Procotyl (Wright) Rim-lock A-Class

Sheet PlanOfExperiments
A1: UHMWPE, Serie.O5, porovnani novych/nepouzitych PE-vlozek, 5 materialu z fy. Beznoska vs. 15 novych UHMWPE z komercnich vlozek pouzivanych v CR
A2: (POZOR: tato serie je formalne ortopedicka, fakticky materialova => na starosti ji ma primo MS, charakterizaci vzorku HV
A3: (plan experimentu, 2017-02-13_MS
A5: Vzorky | D5: Metody | I5: Zdrojova data
A6: Znacka | B6: Popis | C6: Serie/vzorek | D6: IR | E6: MH | F6: DSC | G6: TGA | H6: Solubility | I6: Vzorek | J6: Adresar
A7: B01 | B7: PE | C7: MA0 = M80 | D7: ANO | E7: ANO * | F7: ANO | G7: ANO | H7: ANO | I7: M80 | J7: M:\MIREK.GRA\12PE\SERIE.X\MB\X1_SOUHRN\summary_m8-mb.xlsx
A8: B02 | B8: PE+E | C8: MA0E = M80E | D8: ANO | E8: ANO * | F8: ANO | G8: ANO | H8: ANO | I8: M80E | J8: M:\MIREK.GRA\12PE\SERIE.X\MB\X1_SOUHRN\summary_m8-mb.xlsx
A9: B03 | B9: PE/75kGy/RM | C9: M84 | D9: ANO * | E9: ANO * | F9: ANO | G9: ANO | H9: ANO | I9: M84 | J9: M:\MIREK.GRA\08PE\SERIE.X\M8
A10: B04 | B10: PE/50kGy/RM+E | C10: MC2E | D10: ANO | E10: ANO * | F10: ANO | G10: zatim ne, viz ------> | I10: MC2E | J10: M:\MIREK.GRA\12PE\SERIE.X\MC.2 | N10: (orig.vzorek omylem bez vitE
A11: B05 | B11: PE/100kGy/RM+E | C11: MA2E = M82E | D11: ANO | E11: ANO * | F11: ANO | G11: ANO | H11: ANO | I11: M82E | J11: M:\MIREK.GRA\12PE\SERIE.X\MB\X1_SOUHRN\summary_m8-mb.xlsx
A12: K01 | B12: Doplnit - firma01 | C12: O5/K01 | D12: zmerit | E12: zmerit | F12: zmerit | G12: zmerit | H12: mozna
A13: K02 | B13: Doplnit - firma02 | C13: O5/K02 | D13: zmerit | E13: zmerit | F13: zmerit | G13: zmerit | H13: mozna | K13: Poznamky k naplanovanym merenim:
A14: K03 | B14: Doplnit - firma03 | C14: O5/K03 | D14: zmerit | E14: zmerit | F14: zmerit | G14: zmerit | H14: mozna | K14: 0) Z kazdeho vzorku jen polovinu, 2hou schovat na AGING.
A15: K04 | B15: Doplnit - firma04 | C15: O5/K04 | D15: zmerit | E15: zmerit | F15: zmerit | G15: zmerit | H15: mozna | K15: 1) IR: standardnim zpusobem - H.Vlkova -> M.Brunclikova
A16: K05 | B16: Doplnit - firma05 | C16: O5/K05 | D16: zmerit | E16: zmerit | F16: zmerit | G16: zmerit | H16: mozna | K16: 2) MH: klasika (50gf/6s), postupne - H.Vlkova
A17: K06 | B17: Doplnit - firma06 | C17: O5/K06 | D17: zmerit | E17: zmerit | F17: zmerit | G17: zmerit | H17: mozna | K17: 3) DSC+TGA:
A18: K07 | B18: Doplnit - firma07 | C18: O5/K07 | D18: zmerit | E18: zmerit | F18: zmerit | G18: zmerit | H18: mozna | K18: -> DSC: heating (Tm,CR) + cooling(zpetna CR souvisi s XL)
A19: K08 | B19: Doplnit - firma08 | C19: O5/K08 | D19: zmerit | E19: zmerit | F19: zmerit | G19: zmerit | H19: mozna | K19: -> TGA: urcit pritomnost vit.E, analogicky jako u vzorku O5/B*
A20: K09 | B20: Doplnit - firma09 | C20: O5/K09 | D20: zmerit | E20: zmerit | F20: zmerit | G20: zmerit | H20: mozna | J20: domerit | K20: 4) Solubility, pripande MHI...
A21: K10 | B21: Doplnit - firma10 | C21: O5/K10 | D21: zmerit | E21: zmerit | F21: zmerit | G21: zmerit | H21: mozna | K21: -> zatim ne, vyhledove u vybranych vzorku...
A22: K11 | B22: Doplnit - firma11 | C22: O5/K11 | D22: zmerit | E22: zmerit | F22: zmerit | G22: zmerit | H22: mozna
A23: K12 | B23: Doplnit - firma12 | C23: O5/K12 | D23: zmerit | E23: zmerit | F23: zmerit | G23: zmerit | H23: mozna
A24: K13 | B24: Doplnit - firma13 | C24: O5/K13 | D24: zmerit | E24: zmerit | F24: zmerit | G24: zmerit | H24: mozna
A25: K14 | B25: Doplnit - firma14 | C25: O5/K14 | D25: zmerit | E25: zmerit | F25: zmerit | G25: zmerit | H25: mozna
A26: K15 | B26: Doplnit - firma15 | C26: O5/K15 | D26: zmerit | E26: zmerit | F26: zmerit | G26: zmerit | H26: mozna
A27: K16 | B27: Doplnit - firma16 | C27: O5/K16 | D27: zmerit | E27: zmerit | F27: zmerit | G27: zmerit | H27: mozna
A30: Poznamky ke vzorkum:
A31: * red | B31: pro M84 sice mame jen starsi mereni IR (metoda P = pruchod 2mm destickou), z tohoto mereni lze indexy jen odhadnout => premerit novym zpusobem
A32: * violet | B32: existuji mensi rozdily pro MH mezi seriemi M8, MA, MC => premereno VSE ZNOVU A NAJEDNOU MH(50gf/6s) -> viz Z:\Z_UHMWPE.2\SERIE.O\O5.NEW\MH\VZORKY.B
A33: * fialova | B33: oprava z 2017-06-06 => tyto dva vzorky (1ni mereny postaru, 2hy omylem dodany bez vit.E) dodatecne premerit stejne jako vsechny ostatni
